Workbook

Sheet 00_개요
A1: office2pdf — 리포지터리 정보 구조화 워크북
A2: OOXML(DOCX/XLSX/PPTX) → PDF 변환 Pure-Rust 라이브러리 · 데이터 수집 기준일 2026-07-27 (main 브랜치 얕은 클론 + GitHub 릴리스 페이지)
A4: 1. 프로젝트 식별 정보
B5: 항목 | C5: 값 | D5: 근거 / 비고
B6: 리포지터리 | C6: developer0hye/office2pdf | D6: GitHub 공개 리포지터리
B7: 한 줄 정의 | C7: LibreOffice·Chromium·Docker 비의존 단일 바이너리 OOXML→PDF 변환기 | D7: README 서두
B8: 메인테이너 | C8: Yonghye Kwon (developer0hye) | D8: 릴리스 노트 Contributors
B9: 라이선스 | C9: Apache License 2.0 | D9: LICENSE / Cargo 워크스페이스 메타데이터
B10: 언어 구성 | C10: Rust 99.5% / 기타 0.5% | D10: GitHub Languages
B11: Rust 툴체인 요건 | C11: edition 2024 / rust-version 1.89 / resolver 3 | D11: 루트 Cargo.toml [workspace.package]
B12: 워크스페이스 멤버 | C12: crates/office2pdf (lib), crates/office2pdf-cli (bin: office2pdf) | D12: 루트 Cargo.toml [workspace].members
B13: 최신 배포 버전 | C13: v0.6.4 | D13: GitHub Releases (2026-07-23, github-actions 자동 배포)
B14: 배포 태그 총계 | C14: 정식 릴리스 10건 + 픽스처 배포 1건(fixtures-v1) | D14: git ls-remote --tags
B15: 레이아웃/PDF 백엔드 | C15: Typst 0.14 (typst, typst-pdf, typst-kit) | D15: crates/office2pdf/Cargo.toml
B16: 파서 스택 | C16: docx-rs 0.4, umya-spreadsheet 2, quick-xml 0.38 기반 자체 OOXML 파서 | D16: 동일 매니페스트 + [patch.crates-io]
... B20: 외부 참조 조사 자료 | C20: references/ 하위 벤치마크 조사 문서 21종(INDEX.md 포함) | D20: references/
A22: 2. 외부 링크
B23: crates.io (라이브러리) | C23: https://crates.io/crates/office2pdf
B24: docs.rs (API 문서) | C24: https://docs.rs/office2pdf
B25: GitHub Releases | C25: https://github.com/developer0hye/office2pdf/releases
B26: CI 워크플로 (Actions) | C26: https://github.com/developer0hye/office2pdf/actions/workflows/ci.yml
B27: Typst (렌더링 백엔드) | C27: https://github.com/typst/typst
A29: 3. 시트 구성 안내 (Legend)
B30: 01_대시보드 | C30: 핵심 지표(KPI) 및 계층·포맷·릴리스 차트. 모든 수치는 타 시트 참조 수식.
B31: 02_기능_매트릭스 | C31: 포맷별 지원 기능 × 구현 상태 × PRD 우선순위. 자동 필터·데이터 유효성·아이콘 세트.
B32: 03_CLI_옵션 | C32: CLI 전역 플래그 및 서브커맨드. README 문서화 여부 대조.
B33: 04_라이브러리_API | C33: 공개 함수, ConvertOptions 필드, 열거형, 오류 변형, Cargo 피처.
B34: 05_모듈_인벤토리 | C34: 소스 파일 171개의 계층·대상 포맷·LOC·테스트 수. 정렬/필터용 표 객체.
B35: 06_릴리스_이력 | C35: 태그별 릴리스일·핵심 변경·릴리스 간격(수식).
B36: 07_검증_품질게이트 | C36: CI 잡, 픽스처 코퍼스, 회귀 증적 정책.
B37: 08_의존성 | C37: 크레이트 의존성 및 포크/패치 적용 현황.
B38: 09_리스크_로드맵 | C38: 비기능 요구사항, 구현 단계, 리스크 대응, 문서-구현 격차.
A40: 표기 규칙 — 파란 글씨: 리포지터리에서 직접 수집한 하드코딩 값(스냅샷) · 검정 글씨: 수식으로 산출된 값 · 회색 이탤릭: 출처 및 가정 주석. 모든 정량 지표는 main 브랜치 얕은 클론(2026-07-27)에서 기계적으로 계산했습니다.

Sheet 01_대시보드
A1: 01. 대시보드 — 코드베이스·검증·릴리스 핵심 지표
A2: 모든 수치 셀은 타 시트를 참조하는 수식입니다(하드코딩 없음). 원천: 05_모듈_인벤토리 / 06_릴리스_이력 / 07_검증_품질게이트.
B4: 핵심 지표(KPI)
B5: 소스 파일 수 (.rs) | C5: =COUNTA(05_모듈_인벤토리!$B$5:$B$175) -> 171 | E5: 커밋 픽스처 문서 수 | F5: =07_검증_품질게이트!$D$21 -> 345
B6: 총 LOC | C6: =SUM(05_모듈_인벤토리!$F$5:$F$175) -> 81715 | E6: CI 잡 수 | F6: =COUNTA(07_검증_품질게이트!$B$7:$B$15) -> 9
B7: 프로덕션 LOC | C7: =SUMIF(05_모듈_인벤토리!$E$5:$E$175,"프로덕션",05_모듈_인벤토리!$F$5:$F$175) -> 35576 | E7: 정식 릴리스 수 | F7: =COUNTA(06_릴리스_이력!$B$5:$B$14) -> 10
B8: 테스트 LOC | C8: =SUMIF(05_모듈_인벤토리!$E$5:$E$175,"테스트",05_모듈_인벤토리!$F$5:$F$175) -> 46139 | E8: 버그 수정 시각 증적 디렉터리 | F8: =07_검증_품질게이트!$D$28 -> 129
B9: 테스트 LOC / 프로덕션 LOC | C9: =IFERROR($C$8/$C$7,"") -> 1.2969136 | E9: parser 계층 LOC 비중 | F9: =IFERROR(SUMIFS(05_모듈_인벤토리!$F$5:$F$175,05_모듈_인벤토리!$C$5:$C$175,"parser")/$C$6,"") -> 0.55228538
B10: #[test] 어노테이션 총계 | C10: =SUM(05_모듈_인벤토리!$G$5:$G$175) -> 1662 | E10: 파일당 평균 LOC | F10: =IFERROR(ROUND(AVERAGE(05_모듈_인벤토리!$F$5:$F$175),0),"") -> 478
A13: 차트 원천 데이터 (수식 산출)
B14: 계층 | C14: 프로덕션 LOC | E14: 대상 포맷 | F14: 커밋 픽스처 수 | H14: 대상 포맷 | I14: 소스 파일 수
B15: parser | C15: =SUMIFS(05_모듈_인벤토리!$F$5:$F$175,05_모듈_인벤토리!$C$5:$C$175,$B15,05_모듈_인벤토리!$E$5:$E$175,"프로덕션") -> 23334 | E15: DOCX | F15: =07_검증_품질게이트!$D$18 -> 115 | H15: DOCX | I15: =COUNTIF(05_모듈_인벤토리!$D$5:$D$175,$H15) -> 32
B16: render | C16: =SUMIFS(05_모듈_인벤토리!$F$5:$F$175,05_모듈_인벤토리!$C$5:$C$175,$B16,05_모듈_인벤토리!$E$5:$E$175,"프로덕션") -> 8331 | E16: PPTX | F16: =07_검증_품질게이트!$D$19 -> 92 | H16: PPTX | I16: =COUNTIF(05_모듈_인벤토리!$D$5:$D$175,$H16) -> 29
B17: core | C17: =SUMIFS(05_모듈_인벤토리!$F$5:$F$175,05_모듈_인벤토리!$C$5:$C$175,$B17,05_모듈_인벤토리!$E$5:$E$175,"프로덕션") -> 2727 | E17: XLSX | F17: =07_검증_품질게이트!$D$20 -> 138 | H17: XLSX | I17: =COUNTIF(05_모듈_인벤토리!$D$5:$D$175,$H17) -> 15
B18: ir | C18: =SUMIFS(05_모듈_인벤토리!$F$5:$F$175,05_모듈_인벤토리!$C$5:$C$175,$B18,05_모듈_인벤토리!$E$5:$E$175,"프로덕션") -> 1184 | H18: common | I18: =COUNTIF(05_모듈_인벤토리!$D$5:$D$175,$H18) -> 95
B19: integration-tests | C19: =SUMIFS(05_모듈_인벤토리!$F$5:$F$175,05_모듈_인벤토리!$C$5:$C$175,$B19,05_모듈_인벤토리!$E$5:$E$175,"프로덕션") -> 0
A20: 계층 LOC는 프로덕션 파일(파일명이 _tests.rs 로 끝나지 않는 파일)만 집계합니다. 커밋 픽스처 수는 tests/fixtures/{docx,pptx,xlsx} 하위 실제 문서 파일 수이며, 외부 대량 코퍼스(fixtures-v1, 2,695개)는 저장소에 커밋되지 않아 제외했습니다.

Sheet 02_기능_매트릭스
A1: 02. 지원 기능 매트릭스 — 포맷 × 기능 영역 × 구현 상태 × PRD 우선순위
A2: 구현 상태는 README Features / 릴리스 노트 / main 브랜치 소스 모듈 존재 여부를 교차 확인한 결과입니다. 헤더 행에서 자동 필터를 사용하십시오.
A4: ID | B4: 대상 포맷 | C4: 기능 영역 | D4: OOXML 요소 / 개념 | E4: 구현 상태 | F4: PRD 우선순위 | G4: 상태 가중치 | H4: 근거 (소스 모듈 / 릴리스)
A5: F-001 | B5: DOCX | C5: 본문 텍스트 흐름 | D5: w:p, w:br, w:lastRenderedPageBreak | E5: 구현 완료 | F5: P0 | G5: =IF($E5="구현 완료",1,IF($E5="부분 구현",0.5,0)) -> 1 | H5: parser/docx_text.rs · README Features
A6: F-002 | B6: DOCX | C6: 인라인 문자 서식 | D6: w:rPr (b, i, u, strike, color, sz) | E6: 구현 완료 | F6: P0 | G6: =IF($E6="구현 완료",1,IF($E6="부분 구현",0.5,0)) -> 1 | H6: parser/docx_text.rs · README Features
A7: F-003 | B7: DOCX | C7: 단락 서식·탭 정지 | D7: w:jc, w:ind, w:spacing, w:defaultTabStop | E7: 구현 완료 | F7: P0 | G7: =IF($E7="구현 완료",1,IF($E7="부분 구현",0.5,0)) -> 1 | H7: v0.6.4 PR #401 · PR #403 (grid leading)
A8: F-004 | B8: DOCX | C8: 문서 스타일시트 | D8: styles.xml, w:pStyle, w:rStyle | E8: 구현 완료 | F8: P1 | G8: =IF($E8="구현 완료",1,IF($E8="부분 구현",0.5,0)) -> 1 | H8: parser/docx_styles.rs
A9: F-005 | B9: DOCX | C9: 표 (병합·테두리·음영) | D9: w:tbl, w:tcPr, w:tblLook, w:vMerge | E9: 구현 완료 | F9: P0 | G9: =IF($E9="구현 완료",1,IF($E9="부분 구현",0.5,0)) -> 1 | H9: parser/docx_tables.rs, docx_context_table_style.rs · v0.6.2
A10: F-006 | B10: DOCX | C10: 표 헤더 행 반복 | D10: w:tblHeader | E10: 구현 완료 | F10: P1 | G10: =IF($E10="구현 완료",1,IF($E10="부분 구현",0.5,0)) -> 1 | H10: parser/docx_context_table_header.rs
A11: F-007 | B11: DOCX | C11: 다단계 목록·번호 재시작 | D11: numbering.xml, w:numPr, w:lvlOverride | E11: 구현 완료 | F11: P1 | G11: =IF($E11="구현 완료",1,IF($E11="부분 구현",0.5,0)) -> 1 | H11: parser/docx_lists.rs · v0.6.0 · v0.6.2
A12: F-008 | B12: DOCX | C12: 인라인·부동 이미지 | D12: wp:inline, wp:anchor, a:blip | E12: 구현 완료 | F12: P0 | G12: =IF($E12="구현 완료",1,IF($E12="부분 구현",0.5,0)) -> 1 | H12: parser/docx_media.rs · v0.6.1 (머리글/바닥글 이미지)
A13: F-009 | B13: DOCX | C13: 레거시 벡터 이미지 | D13: EMF, WMF, VML(v:shape), WPG 그룹 | E13: 구현 완료 | F13: P3 | G13: =IF($E13="구현 완료",1,IF($E13="부분 구현",0.5,0)) -> 1 | H13: parser/docx_context_vml.rs, wmf.rs · v0.6.2
A14: F-010 | B14: DOCX | C14: 드로잉 도형·커넥터 | D14: wps:wsp, a:prstGeom, 텍스트 상자 | E14: 구현 완료 | F14: P3 | G14: =IF($E14="구현 완료",1,IF($E14="부분 구현",0.5,0)) -> 1 | H14: parser/docx_context_shape.rs · v0.6.0 (issue #176)
A15: F-011 | B15: DOCX | C15: 머리글 / 바닥글 | D15: w:hdr, w:ftr, 페이지 번호 필드 | E15: 구현 완료 | F15: P1 | G15: =IF($E15="구현 완료",1,IF($E15="부분 구현",0.5,0)) -> 1 | H15: parser/docx_sections.rs · v0.6.1 · v0.6.2
A16: F-012 | B16: DOCX | C16: 페이지 설정·다단 편집 | D16: w:sectPr, w:pgSz, w:pgMar, w:cols | E16: 구현 완료 | F16: P1 | G16: =IF($E16="구현 완료",1,IF($E16="부분 구현",0.5,0)) -> 1 | H16: parser/docx_context_columns.rs
... A71: F-067 | B71: 공통 | C71: HTTP 변환 서버 | D71: CLI server 서브커맨드 (tiny_http) | E71: 구현 완료 | F71: 미분류 | G71: =IF($E71="구현 완료",1,IF($E71="부분 구현",0.5,0)) -> 1 | H71: office2pdf-cli/src/server.rs (server 피처) · README 미기재
A73: 요약 (필터 적용과 무관한 전체 집계)
C74: 전체 기능 항목 수 | D74: =COUNTA($A$5:$A$71) -> 67
C75: 구현 완료 | D75: =COUNTIF($E$5:$E$71,"구현 완료") -> 59
C76: 부분 구현 | D76: =COUNTIF($E$5:$E$71,"부분 구현") -> 4
C77: 코드 근거 미확인 | D77: =COUNTIF($E$5:$E$71,"코드 근거 미확인") -> 2
C78: 미지원 | D78: =COUNTIF($E$5:$E$71,"미지원") -> 2
C79: 가중 구현률(상태 가중치 평균) | D79: =IFERROR(AVERAGE($G$5:$G$71),"") -> 0.91044776
C80: P0 항목 중 구현 완료 비율 | D80: =IFERROR(COUNTIFS($F$5:$F$71,"P0",$E$5:$E$71,"구현 완료")/COUNTIF($F$5:$F$71,"P0"),"") -> 1
A81: '코드 근거 미확인'은 README 등 문서에 기재되어 있으나 main 브랜치 소스에서 해당 처리 모듈을 특정하지 못한 항목입니다(미지원 확정이 아님). 'README 미기재'로 표시된 근거는 반대로 소스에는 존재하나 README Features에 노출되지 않은 기능입니다.

Sheet 03_CLI_옵션
A1: 03. CLI 인터페이스 — 전역 플래그 및 서브커맨드
A2: 출처: crates/office2pdf-cli/src/main.rs 의 clap derive 정의 및 README 'CLI Options' 표. 'README 문서화' 열로 문서-구현 격차를 식별할 수 있습니다.
A4: 구분 | B4: 플래그 / 커맨드 | C4: 축약 | D4: 값 형식 | E4: 기본값 | F4: 적용 포맷 | G4: 설명 | H4: README 문서화 | I4: 비고
A5: 전역 인자 | B5: <INPUTS>... | C5: - | D5: 경로 목록 | E5: 필수 | F5: 전체 | G5: 변환할 입력 파일 경로(.docx/.xlsx/.pptx). 글롭 확장으로 일괄 변환 가능 | H5: 기재 | I5: required = true
A6: 전역 플래그 | B6: --output | C6: -o | D6: PATH | E6: 입력 파일명.pdf | F6: 전체 | G6: 출력 PDF 경로. 단일 입력에만 유효 | H6: 기재 | I6: --outdir와 상호 배타
A7: 전역 플래그 | B7: --outdir | C7: - | D7: DIR | E7: 입력 파일과 동일 위치 | F7: 전체 | G7: 일괄 변환 결과를 저장할 출력 디렉터리 | H7: 기재 | I7: conflicts_with = output
A8: 전역 플래그 | B8: --paper | C8: - | D8: a4 | letter | legal | E8: 원본 문서 크기 | F8: 전체 | G8: 출력 용지 크기 강제 지정 | H8: 기재 | I8: PaperSize::parse (대소문자 무시)
A9: 전역 플래그 | B9: --landscape | C9: - | D9: 플래그 | E9: 원본 방향 유지 | F9: 전체 | G9: 가로 방향 강제(너비>높이로 치수 교환) | H9: 기재 | I9: Option<bool> 3상태
A10: 전역 플래그 | B10: --pdf-a | C10: - | D10: 플래그 | E10: PDF 1.7 | F10: 전체 | G10: PDF/A-2b 보존용 준수 출력 | H10: 기재 | I10: PdfStandard::PdfA2b
A11: 전역 플래그 | B11: --sheets | C11: - | D11: 이름 목록(콤마) | E11: 전체 시트 | F11: XLSX | G11: 변환 대상 시트 이름 필터 | H11: 기재 | I11: value_delimiter = ','
A12: 전역 플래그 | B12: --slides | C12: - | D12: 범위 (예: 1-5, 3) | E12: 전체 슬라이드 | F12: PPTX | G12: 변환 대상 슬라이드 범위(1-기반, 양끝 포함) | H12: 기재 | I12: SlideRange::parse
A13: 전역 플래그 | B13: --font-path | C13: - | D13: DIR (반복 가능) | E13: 시스템/내장 폰트 | F13: 전체 | G13: 추가 폰트 탐색 디렉터리 | H13: 기재 | I13: macOS는 Office 폰트 자동 탐색이 선행
A14: 전역 플래그 | B14: --tagged | C14: - | D14: 플래그 | E14: false | F14: 전체 | G14: 접근성 구조 태그(H1~H6, P, Table, Figure) 포함 태그 PDF 생성 | H14: 미기재 | I14: README CLI Options 표에 없음
A15: 전역 플래그 | B15: --pdf-ua | C15: - | D15: 플래그 | E15: false | F15: 전체 | G15: PDF/UA-1 보편적 접근성 준수 출력(--tagged 함의) | H15: 미기재 | I15: README CLI Options 표에 없음
... A23: 정보 플래그 | B23: --version / --help | C23: -V / -h | D23: 플래그 | E23: - | F23: - | G23: 버전 및 사용법 출력 | H23: 기재(PRD) | I23: clap 기본 제공
A25: README 미기재 항목 수 | B25: =COUNTIF($H$5:$H$23,"미기재") -> 9 | C25: ← README 'CLI Options' 표에 노출되지 않은 구현 완료 항목 (전역 플래그 6건 + 서브커맨드 3건, 문서 갱신 후보)

Sheet 04_라이브러리_API
A1: 04. 라이브러리 공개 API · 설정 · 오류 · 피처
A2: 출처: crates/office2pdf/src/{lib.rs, config.rs, error.rs, wasm.rs}, Cargo.toml [features], README Quick Start.
A4: 1. Rust 공개 함수 (crate root)
B5: 시그니처 | C5: 반환 | D5: 입력 | E5: 설명
B6: office2pdf::convert(path) | C6: Result<ConvertResult> | D6: 파일 경로 | E6: 확장자로 포맷을 판별해 기본 옵션으로 변환하는 원라이너
B7: office2pdf::convert_with_options(path, &opts) | C7: Result<ConvertResult> | D7: 파일 경로 + ConvertOptions | E7: 용지·시트·슬라이드·폰트 등 옵션을 적용한 변환
B8: office2pdf::convert_bytes(&bytes, Format, &opts) | C8: Result<ConvertResult> | D8: 바이트 슬라이스 + 명시적 Format | E8: 파일 시스템 경유 없이 메모리 상에서 변환
A10: 2. WASM 바인딩 (wasm 피처 · wasm-bindgen)
B11: convertToPdf(data, format) | C11: Uint8Array | D11: 바이트 + 포맷 문자열 | E11: 포맷 문자열("docx"/"xlsx"/"pptx")을 받는 범용 진입점
B12: convertDocxToPdf(data) | C12: Uint8Array | D12: 바이트 | E12: DOCX 전용 진입점
B13: convertPptxToPdf(data) | C13: Uint8Array | D13: 바이트 | E13: PPTX 전용 진입점
B14: convertXlsxToPdf(data) | C14: Uint8Array | D14: 바이트 | E14: XLSX 전용 진입점
A15: 빌드: wasm-pack build crates/office2pdf --target web --features wasm · wasm32 타깃에서는 web-time으로 std::time 패닉을 우회하고 getrandom 0.2/0.3을 js 백엔드로 고정합니다.
A17: 3. ConvertOptions 필드
B18: 필드 | C18: 타입 | D18: 기본값 | E18: 설명
B19: sheet_names | C19: Option<Vec<String>> | D19: None (전체 시트) | E19: XLSX 시트 이름 화이트리스트 필터
B20: slide_range | C20: Option<SlideRange> | D20: None (전체 슬라이드) | E20: PPTX 슬라이드 범위(1-기반, 양끝 포함)
B21: pdf_standard | C21: Option<PdfStandard> | D21: None (PDF 1.7) | E21: PDF/A-2b 등 준수 표준 강제
B22: paper_size | C22: Option<PaperSize> | D22: None (원본 크기) | E22: 출력 용지 크기 재정의
B23: font_paths | C23: Vec<PathBuf> | D23: 빈 벡터 | E23: 추가 폰트 탐색 경로
B24: landscape | C24: Option<bool> | D24: None (원본 방향) | E24: Some(true)=가로, Some(false)=세로 강제
B25: tagged | C25: bool | D25: false | E25: 문서 구조 태그 포함 접근성 PDF 생성
B26: pdf_ua | C26: bool | D26: false | E26: PDF/UA-1 준수(tagged 함의)
B27: streaming | C27: bool | D27: false | E27: XLSX 행 청크 스트리밍 처리(pdf-ops 피처 필요)
B28: streaming_chunk_size | C28: Option<usize> | D28: None → 1000행 | E28: 스트리밍 청크 크기
A30: 4. 열거형 및 값 도메인
B31: Format | C31: Docx | Xlsx | Pptx | D31: from_extension 으로 확장자 판별 | E31: 포맷 명시 또는 자동 판별
B32: PaperSize | C32: A4 | Letter | Legal | Custom(w,h) | D32: A4=595.28×841.89pt, Letter=612×792pt, Legal=612×1008pt | E32: 포인트 단위 치수 반환
B33: PdfStandard | C33: PdfA2b | D33: 보존(archival) 목적 준수 프로파일 | E33: --pdf-a 에 대응
B34: SlideRange | C34: { start: u32, end: u32 } | D34: "1-5" 또는 "3" 파싱, 1-기반 양끝 포함 | E34: contains(n) 로 포함 여부 판정
A36: 5. 오류 타입 (thiserror 기반 Error 열거형)
B37: UnsupportedFormat(String) | C37: 지원하지 않는 파일 포맷 | D37: - | E37: 확장자/포맷 판별 실패
B38: Io(std::io::Error) | C38: 입출력 오류 | D38: #[from] 변환 | E38: 파일 읽기/쓰기 실패
B39: Parse(String) | C39: 파싱 오류 | D39: - | E39: OOXML 파싱 단계 실패
B40: Render(String) | C40: 렌더링 오류 | D40: - | E40: Typst 컴파일/PDF 내보내기 실패
B41: EncryptedFile | C41: 암호/보호된 파일 | D41: - | E41: 복호화 불가로 변환 중단
B42: UnsupportedElement / PartialElement / FallbackUsed / ParseSkipped | C42: 부분 실패 진단 정보 | D42: 구조체 변형 | E42: 요소를 건너뛰되 전체 변환은 계속하는 정책의 경고 채널
A44: 6. Cargo 피처 플래그
B45: office2pdf / wasm | C45: wasm-bindgen | D45: 기본 비활성 | E45: 브라우저·Node.js용 WASM 바인딩 노출
B46: office2pdf / pdf-ops | C46: lopdf 0.39 | D46: 기본 비활성 | E46: PDF 병합·분할 및 스트리밍 모드의 청크 병합
...

Sheet 05_모듈_인벤토리
A1: 05. 소스 모듈 인벤토리 — 계층 / 대상 포맷 / LOC / 단위 테스트 수
A2: main 브랜치 얕은 클론에서 crates/**/src/**/*.rs 및 crates/office2pdf/tests/*.rs 를 기계적으로 집계했습니다. LOC는 공백·주석을 포함한 물리적 행 수이며, 테스트 수는 #[test] / #[wasm_bindgen_test] 어노테이션 개수입니다.
B3: 필터 반영 합계 (SUBTOTAL) → | F3: =SUBTOTAL(109,$F$5:$F$175) -> 81715 | G3: =SUBTOTAL(109,$G$5:$G$175) -> 1662 | H3: =SUBTOTAL(109,$H$5:$H$175) -> 1
A4: 크레이트 | B4: 경로 (src/ 기준) | C4: 계층 | D4: 대상 포맷 | E4: 파일 성격 | F4: LOC | G4: #[test] 수 | H4: LOC 비중
A5: office2pdf | B5: config.rs | C5: core | D5: common | E5: 프로덕션 | F5: 164 | G5: 0 | H5: =IFERROR($F5/SUM($F$5:$F$175),"") -> 0.0020069755
A6: office2pdf | B6: config_tests.rs | C6: core | D6: common | E6: 테스트 | F6: 241 | G6: 29 | H6: =IFERROR($F6/SUM($F$5:$F$175),"") -> 0.0029492749
A7: office2pdf | B7: config_ts_tests.rs | C7: core | D7: common | E7: 테스트 | F7: 71 | G7: 7 | H7: =IFERROR($F7/SUM($F$5:$F$175),"") -> 0.00086887352
A8: office2pdf | B8: defaults.rs | C8: core | D8: common | E8: 프로덕션 | F8: 69 | G8: 0 | H8: =IFERROR($F8/SUM($F$5:$F$175),"") -> 0.00084439821
A9: office2pdf | B9: defaults_tests.rs | C9: core | D9: common | E9: 테스트 | F9: 103 | G9: 15 | H9: =IFERROR($F9/SUM($F$5:$F$175),"") -> 0.0012604785
A10: office2pdf | B10: error.rs | C10: core | D10: common | E10: 프로덕션 | F10: 140 | G10: 0 | H10: =IFERROR($F10/SUM($F$5:$F$175),"") -> 0.0017132717
A11: office2pdf | B11: error_tests.rs | C11: core | D11: common | E11: 테스트 | F11: 208 | G11: 15 | H11: =IFERROR($F11/SUM($F$5:$F$175),"") -> 0.0025454323
A12: office2pdf | B12: error_ts_tests.rs | C12: core | D12: common | E12: 테스트 | F12: 53 | G12: 4 | H12: =IFERROR($F12/SUM($F$5:$F$175),"") -> 0.00064859573
A13: office2pdf | B13: lib.rs | C13: core | D13: common | E13: 프로덕션 | F13: 175 | G13: 0 | H13: =IFERROR($F13/SUM($F$5:$F$175),"") -> 0.0021415897
A14: office2pdf | B14: lib_conversion_tests.rs | C14: core | D14: common | E14: 테스트 | F14: 283 | G14: 12 | H14: =IFERROR($F14/SUM($F$5:$F$175),"") -> 0.0034632564
A15: office2pdf | B15: lib_pipeline.rs | C15: core | D15: common | E15: 프로덕션 | F15: 428 | G15: 0 | H15: =IFERROR($F15/SUM($F$5:$F$175),"") -> 0.0052377165
A16: office2pdf | B16: lib_pipeline_tests.rs | C16: core | D16: common | E16: 테스트 | F16: 337 | G16: 21 | H16: =IFERROR($F16/SUM($F$5:$F$175),"") -> 0.0041240898
... A175: office2pdf-cli | B175: server_tests.rs | C175: core | D175: common | E175: 테스트 | F175: 504 | G175: 16 | H175: =IFERROR($F175/SUM($F$5:$F$175),"") -> 0.0061677783
A177: 계층별 집계 (전체 데이터 기준, 필터 무관)
A178: 계층 | B178: 설명 | C178: 파일 수 | D178: 프로덕션 LOC | E178: 테스트 LOC | F178: 총 LOC | G178: #[test] 수 | H178: LOC 비중
A179: parser | B179: OOXML 패키지 파싱 → 중간 표현(IR) 생성 | C179: =COUNTIF($C$5:$C$175,$A179) -> 98 | D179: =SUMIFS($F$5:$F$175,$C$5:$C$175,$A179,$E$5:$E$175,"프로덕션") -> 23334 | E179: =SUMIFS($F$5:$F$175,$C$5:$C$175,$A179,$E$5:$E$175,"테스트") -> 21796 | F179: =$D179+$E179 -> 45130 | G179: =SUMIF($C$5:$C$175,$A179,$G$5:$G$175) -> 773 | H179: =IFERROR($F179/SUM($F$5:$F$175),"") -> 0.55228538
A180: render | B180: IR → Typst 마크업 코드 생성 및 PDF 내보내기 | C180: =COUNTIF($C$5:$C$175,$A180) -> 30 | D180: =SUMIFS($F$5:$F$175,$C$5:$C$175,$A180,$E$5:$E$175,"프로덕션") -> 8331 | E180: =SUMIFS($F$5:$F$175,$C$5:$C$175,$A180,$E$5:$E$175,"테스트") -> 13667 | F180: =$D180+$E180 -> 21998 | G180: =SUMIF($C$5:$C$175,$A180,$G$5:$G$175) -> 459 | H180: =IFERROR($F180/SUM($F$5:$F$175),"") -> 0.26920394
A181: core | B181: 공개 API, 변환 파이프라인, 설정·오류·기본값, WASM 바인딩 | C181: =COUNTIF($C$5:$C$175,$A181) -> 27 | D181: =SUMIFS($F$5:$F$175,$C$5:$C$175,$A181,$E$5:$E$175,"프로덕션") -> 2727 | E181: =SUMIFS($F$5:$F$175,$C$5:$C$175,$A181,$E$5:$E$175,"테스트") -> 4388 | F181: =$D181+$E181 -> 7115 | G181: =SUMIF($C$5:$C$175,$A181,$G$5:$G$175) -> 240 | H181: =IFERROR($F181/SUM($F$5:$F$175),"") -> 0.087070917
A182: ir | B182: 포맷 독립 문서 모델(Document/Page/Block/Style) | C182: =COUNTIF($C$5:$C$175,$A182) -> 8 | D182: =SUMIFS($F$5:$F$175,$C$5:$C$175,$A182,$E$5:$E$175,"프로덕션") -> 1184 | E182: =SUMIFS($F$5:$F$175,$C$5:$C$175,$A182,$E$5:$E$175,"테스트") -> 730 | F182: =$D182+$E182 -> 1914 | G182: =SUMIF($C$5:$C$175,$A182,$G$5:$G$175) -> 32 | H182: =IFERROR($F182/SUM($F$5:$F$175),"") -> 0.023422872
A183: integration-tests | B183: 픽스처 기반 통합·성능·시각 회귀 테스트 하네스 | C183: =COUNTIF($C$5:$C$175,$A183) -> 8 | D183: =SUMIFS($F$5:$F$175,$C$5:$C$175,$A183,$E$5:$E$175,"프로덕션") -> 0 | E183: =SUMIFS($F$5:$F$175,$C$5:$C$175,$A183,$E$5:$E$175,"테스트") -> 5558 | F183: =$D183+$E183 -> 5558 | G183: =SUMIF($C$5:$C$175,$A183,$G$5:$G$175) -> 158 | H183: =IFERROR($F183/SUM($F$5:$F$175),"") -> 0.068016888
A184: 합계 | C184: =SUM(C179:C183) -> 171 | D184: =SUM(D179:D183) -> 35576 | E184: =SUM(E179:E183) -> 46139 | F184: =SUM(F179:F183) -> 81715 | G184: =SUM(G179:G183) -> 1662 | H184: =SUM(H179:H183) -> 1
A186: 파일 성격 분류 규칙: 파일명이 _tests.rs 로 끝나거나 crates/office2pdf/tests/ 하위에 위치하면 '테스트'로 분류했습니다. 프로덕션 모듈과 테스트 모듈을 동일 디렉터리에 짝으로 배치하고 #[path] 어트리뷰트로 포함하는 것이 이 리포지터리의 관례입니다.

Sheet 06_릴리스_이력
A1: 06. 릴리스 이력 — 태그 · 배포일 · 핵심 변경 · 릴리스 간격
A2: 출처: GitHub Releases 페이지(2026-07-27 조회) 및 git ls-remote --tags. 경과일 열은 날짜 차이 수식으로 산출합니다.
A4: 순번 | B4: 태그 | C4: 릴리스일 | D4: 배포 주체 | E4: 유형 | F4: 핵심 변경 요약 | G4: 이전 대비 경과일 | H4: v0.2.0 기준 누적일
A5: 1 | B5: v0.1.0 | D5: developer0hye | E5: 초기 공개 | F5: 초기 공개 버전(릴리스 목록 2페이지에 위치하여 본 수집에서는 날짜 미확인) | H5: =IF($C5="","",$C5-$C$6)
A6: 2 | B6: v0.2.0 | C6: 46080 | D6: developer0hye | E6: 기능 추가 | F6: PPTX 그라디언트 배경, 도형 그림자/반사 효과, XLSX DataBar·IconSet 조건부 서식, 성능 벤치마크 도입, 실사용 픽스처 27→147개 확대 | G6: =IF(OR($C6="",$C5=""),"",$C6-$C5) | H6: =IF($C6="","",$C6-$C$6) -> 0
A7: 3 | B7: v0.3.0 | C7: 46080 | D7: developer0hye | E7: 플랫폼 확장 | F7: WASM 지원: 조건부 컴파일 가드, getrandom 등 의존성 WASM 이슈 해소, wasm-bindgen JS API 4함수, CI에 WASM 검사·통합 테스트 추가 | G7: =IF(OR($C7="",$C6=""),"",$C7-$C6) -> 0 | H7: =IF($C7="","",$C7-$C$6) -> 0
A8: 4 | B8: v0.4.0 | C8: 46095 | D8: developer0hye | E8: 기능 추가 | F8: PPTX tableStyles.xml 기반 테마 표 스타일, tint/shade 색 변환, 커넥터 도형, 임베드 폰트 추출·난독 해제, macOS Office 폰트 자동 탐색, 대규모 모듈 리팩터링 | G8: =IF(OR($C8="",$C7=""),"",$C8-$C7) -> 15 | H8: =IF($C8="","",$C8-$C$6) -> 15
A9: 5 | B9: v0.5.0 | C9: 46096 | D9: developer0hye | E9: 충실도 개선 | F9: PPTX homePlate 도형, fillRef/fontRef 스타일 폴백, custGeom 렌더, 마스터/레이아웃 자리표시자 처리, 정렬을 #set align()으로 전환 | G9: =IF(OR($C9="",$C8=""),"",$C9-$C8) -> 1 | H9: =IF($C9="","",$C9-$C$6) -> 16
A10: 6 | B10: v0.6.0 | C10: 46174 | D10: developer0hye | E10: 충실도 개선 | F10: DOCX 부동 드로잉 충실도(issue #176), 목록 연속·중첩 개선, 코드 블록 강제 개행·구문 강조 유지, 표 테두리 명시 렌더, WASM 안정성 개선 | G10: =IF(OR($C10="",$C9=""),"",$C10-$C9) -> 78 | H10: =IF($C10="","",$C10-$C$6) -> 94
A11: 7 | B11: v0.6.1 | C11: 46214 | D11: developer0hye | E11: 버그 수정 | F11: DOCX 머리글/바닥글 관계 파트의 인라인 이미지 유지, 바닥글 RTL 방향 보존, 다단락·이미지 바닥글 스택 정렬, crates.io 릴리스 워크플로 자동화 | G11: =IF(OR($C11="",$C10=""),"",$C11-$C10) -> 40 | H11: =IF($C11="","",$C11-$C$6) -> 134
A12: 8 | B12: v0.6.2 | C12: 46219 | D12: developer0hye | E12: 버그 수정 | F12: DOCX 단순 필드·런 페이지 나눔·바닥글 레이아웃 보존, EMF/WMF/VML/WPG 이미지 충실도, RTL 표 시각 순서 및 병합 셀 조건부 음영, 대량 변환 기준선 CI 게이트 추가 | G12: =IF(OR($C12="",$C11=""),"",$C12-$C11) -> 5 | H12: =IF($C12="","",$C12-$C$6) -> 139
A13: 9 | B13: v0.6.3 | C13: 46225 | D13: developer0hye | E13: 충실도 개선 | F13: XLSX 인쇄·렌더 충실도 대폭 개선(페이지네이션·인쇄 제목·이미지·텍스트 상자·차트·조건부 서식), PPTX 배경/차트/SmartArt 확장, 6개 플랫폼 프리빌트 CLI 아카이브 추가, crates.io 패키지 이식성 수정 | G13: =IF(OR($C13="",$C12=""),"",$C13-$C12) -> 6 | H13: =IF($C13="","",$C13-$C$6) -> 145
A14: 10 | B14: v0.6.4 | C14: 46226 | D14: github-actions | E14: 버그 수정 | F14: PPTX 그림자 블러 근사(#400), DOCX 탭 정지·격자 행간·표 셀 행 높이(#401·#403·#405·#409), XLSX IconSet 임계값·삼각형 아이콘·셀 채움·인쇄 행 기하(#407·#408·#410·#412), 비즈니스 골든 목 코퍼스 도입 | G14: =IF(OR($C14="",$C13=""),"",$C14-$C13) -> 1 | H14: =IF($C14="","",$C14-$C$6) -> 146
E16: 릴리스 총 건수 | F16: =COUNTA($B$5:$B$14) -> 10
E17: 날짜 확인된 릴리스 | F17: =COUNT($C$5:$C$14) -> 9
E18: 평균 릴리스 간격(일) | F18: =IFERROR(ROUND(AVERAGE($G$6:$G$14),1),"") -> 18.3
E19: 최단 / 최장 간격(일) | F19: =_xlfn.CONCAT(MIN($G$6:$G$14)," / ",MAX($G$6:$G$14)) -> 0 / 78
E20: v0.2.0 → v0.6.4 총 기간(일) | F20: =$C$14-$C$6 -> 146
E21: v0.6.x 계열 릴리스 수 | F21: =COUNTIF($B$5:$B$14,"v0.6*") -> 5
A22: v0.6.x 계열 5건이 2026-06-01 ~ 2026-07-23 사이에 집중되어 있으며, 이 기간의 변경은 대부분 시각 회귀 증적을 첨부한 충실도(fidelity) 버그 수정입니다. v0.6.4는 GitHub Actions에 의해 자동 배포되었습니다.

Sheet 07_검증_품질게이트
A1: 07. 검증 체계 — CI 품질 게이트 · 픽스처 코퍼스 · 회귀 증적
A2: 출처: .github/workflows/ci.yml, tests/ 디렉터리 실측, fixtures-v1 릴리스 노트, AGENTS/RELEASING 관례.
A4: 1. CI 워크플로 잡 (.github/workflows/ci.yml)
A5: 트리거: push / pull_request. check·test 잡은 ubuntu-latest, windows-latest, macos-latest 3중 매트릭스로 실행됩니다.
B6: 잡 ID | C6: 표시명 | D6: 러너 | E6: 목적 및 게이트 성격
B7: release-contract | C7: Release Automation Contract | D7: ubuntu-latest | E7: 릴리스 자동화 계약 검증 — 버전·태그·워크플로 정합성 확인
B8: business-golden-contract | C8: Business Golden Contract | D8: ubuntu-latest | E8: 비즈니스 골든 목 코퍼스 검증(scripts/validate_business_golden_mocks.py)
B9: visual-pr-contract | C9: Visual PR Contract | D9: ubuntu-latest | E9: 버그 수정 PR의 before/after 시각 증적 첨부 강제(scripts/check_visual_pr.py)
B10: check | C10: Check | D10: 3중 OS 매트릭스 | E10: cargo check — 컴파일 가능성 확인
B11: test | C11: Test | D11: 3중 OS 매트릭스 | E11: cargo test --workspace — 단위·통합 테스트 전량 실행
B12: clippy | C12: Clippy | D12: ubuntu-latest | E12: 린트 게이트 — 경고를 오류로 취급
B13: wasm-check | C13: WASM Check & Test | D13: ubuntu-latest | E13: wasm32 무피처 빌드 + wasm-pack 통합 테스트
B14: fmt | C14: Format | D14: ubuntu-latest | E14: cargo fmt --check — 서식 일관성
B15: bulk-test | C15: Bulk Third-Party Fixture Test | D15: ubuntu-latest | E15: 외부 대량 코퍼스 회귀 게이트(기준선 대조, #[ignore] 해제 실행)
A16: 2. 테스트 픽스처 코퍼스
B17: 구분 | C17: 위치 | D17: 수량 | E17: 비고
B18: 커밋 픽스처 — DOCX | C18: tests/fixtures/docx/ | D18: 115 | E18: 책갈피·체크박스·변경 추적·미주·필드 코드·중첩 표·드로잉 등
B19: 커밋 픽스처 — PPTX | C19: tests/fixtures/pptx/ | D19: 92 | E19: 차트·SmartArt·임베드 미디어·표·테마·일본어 텍스트·애니메이션
B20: 커밋 픽스처 — XLSX | C20: tests/fixtures/xlsx/ | D20: 138 | E20: 피벗 테이블·수식·인라인 문자열·그룹 행·RTL·차트·불리언
B21: 커밋 픽스처 합계 | D21: =SUM($D$18:$D$20) -> 345 | E21: 개방 라이선스(CC0 / Apache-2.0 / MIT) 출처의 실사용 문서 집합
B22: 골든 목 — 원본 문서 | C22: tests/golden_mocks/business/ | D22: 30 | E22: 비즈니스 시나리오 DOCX/PPTX/XLSX 각 10건 (v0.6.4 도입)
B23: 골든 목 — 기준 PDF | C23: tests/golden_mocks/business/ | D23: 30 | E23: 원본 대응 기준 PDF 30건 + 메타데이터 JSON 2건
B24: 외부 대량 코퍼스 | C24: fixtures-v1 릴리스 자산 | D24: 2695 | E24: LibreOffice/core · apache/poi 출처, 저장소에 커밋하지 않고 릴리스 자산으로 배포(sha256 검증, Git LFS 대역폭 회피)
B25: 시각 감사 자료 | C25: tests/visual_audits/ | D25: 2 | E25: 공개 이슈 기반 시각 감사 산출물
A27: 3. 회귀 증적 및 개발 관례
B28: 버그 수정 시각 증적 | C28: assets/bugfixes/issue-*/ | D28: 129 | E28: 이슈 번호별 before.png / after.png 증적 디렉터리. visual-pr-contract 잡이 첨부를 강제
B29: 대량 변환 기준선 | C29: crates/office2pdf/tests/bulk_conversion.rs | E29: 외부 코퍼스 변환 결과를 커밋된 기준선과 대조(#[ignore] 지정, bulk-test 잡에서 실행)
B30: PDF 유효성 검증 | C30: tests/pdf_validation.rs | E30: 생성 PDF의 구조 유효성 및 텍스트 추출 기반 왕복(round-trip) 검증
B31: 성능 검증 | C31: tests/perf_validation.rs + benches/conversion.rs | E31: criterion 벤치마크. CI는 변환당 30초 안전 상한만 적용하며 이는 제품 SLA가 아님(v0.6.4에서 불안정한 예산 대신 상한으로 전환)
B32: 의존성 결함 대응 정책 | C32: [patch.crates-io] + 포크 | E32: PDF 변환 결함은 상류(docx-rs, umya-spreadsheet)에 수정 후 포크 브랜치로 고정하는 정책을 문서화(v0.6.2)
B33: 에이전트 협업 규약 | C33: AGENTS.md / CLAUDE.md / .claude, .codex | E33: 코딩 에이전트용 리포지터리 규약 및 서브에이전트 정의를 리포지터리에 함께 관리
A35: 4. 자동화 테스트 규모 (05_모듈_인벤토리 참조 수식)
B36: 테스트 파일 수 (_tests.rs 및 tests/) | D36: =COUNTIF(05_모듈_인벤토리!$E$5:$E$175,"테스트") -> 94
B37: 프로덕션 파일 수 | D37: =COUNTIF(05_모듈_인벤토리!$E$5:$E$175,"프로덕션") -> 77
B38: #[test] 어노테이션 총계 | D38: =SUM(05_모듈_인벤토리!$G$5:$G$175) -> 1662
B39: 통합 테스트 하네스 파일 수 | D39: =COUNTIF(05_모듈_인벤토리!$C$5:$C$175,"integration-tests") -> 8
B40: 테스트 LOC 비중(전체 LOC 대비) | D40: =IFERROR(SUMIF(05_모듈_인벤토리!$E$5:$E$175,"테스트",05_모듈_인벤토리!$F$5:$F$175)/SUM(05_모듈_인벤토리!$F$5:$F$175),"") -> 0.56463318
B41: 프로덕션 파일당 평균 테스트 수 | D41: =IFERROR(SUM(05_모듈_인벤토리!$G$5:$G$175)/COUNTIF(05_모듈_인벤토리!$E$5:$E$175,"프로덕션"),"") -> 21.584416
A43: PRD 9장의 검증 방법론: 골든 테스트(문서→PDF→스크린샷 비교), 왕복 검증(텍스트 추출), MS Office 출력과의 수동 대조, 커밋 단위 CI 자동 변환. 시각 회귀는 scripts/compare_render.py 로 렌더 결과를 비교합니다.

Sheet 08_의존성
A1: 08. 의존성 인벤토리 — 크레이트 · 버전 · 역할 · 포크 적용 현황
A2: 출처: 루트 Cargo.toml([patch.crates-io]) 및 crates/office2pdf, crates/office2pdf-cli 매니페스트.
A4: 크레이트 | B4: 버전 | C4: 소속 | D4: 구분 | E4: 역할 | F4: 포크/패치 | G4: crates.io | H4: 비고
A5: typst | B5: 0.14 | C5: office2pdf | D5: 런타임 필수 | E5: 레이아웃 엔진 — 생성된 Typst 마크업을 조판 | F5: - | G5: crates.io | H5: 프로젝트의 핵심 아키텍처 결정
A6: typst-pdf | B6: 0.14 | C6: office2pdf | D6: 런타임 필수 | E6: Typst 문서 → PDF 내보내기(PDF/A·태그 옵션 포함) | F6: - | G6: crates.io
A7: typst-kit | B7: 0.14 | C7: office2pdf | D7: 런타임 필수 | E7: 폰트 탐색 및 폰트 임베딩(fonts, embed-fonts 피처) | F7: - | G7: crates.io | H7: default-features = false
A8: comemo | B8: 0.5 | C8: office2pdf | D8: 런타임 필수 | E8: Typst의 증분 계산 메모이제이션 | F8: - | G8: crates.io
A9: docx-rs | B9: 0.4 | C9: office2pdf | D9: 런타임 필수 | E9: DOCX(WordprocessingML) 파싱 | F9: 포크 적용 | G9: crates.io | H9: fix/parse-tolerance 브랜치로 패치
A10: umya-spreadsheet | B10: 2 | C10: office2pdf | D10: 런타임 필수 | E10: XLSX(SpreadsheetML) 파싱 및 서식 추출 | F10: 포크 적용 | G10: crates.io | H10: fix/panic-safety-v2 브랜치로 패치
A11: quick-xml | B11: 0.38 | C11: office2pdf | D11: 런타임 필수 | E11: PPTX 등 자체 OOXML 파서의 스트리밍 XML 처리 | F11: - | G11: crates.io | H11: PPTX는 전용 파서를 자체 구현
A12: zip | B12: 0.6 | C12: office2pdf | D12: 런타임 필수 | E12: OOXML 패키지(OPC) 압축 해제 | F12: - | G12: crates.io | H12: deflate 피처만 사용
A13: image | B13: 0.25 | C13: office2pdf | D13: 런타임 필수 | E13: 래스터 이미지 디코드 및 치수 산출 | F13: - | G13: crates.io
A14: unicode-normalization | B14: 0.1 | C14: office2pdf | D14: 런타임 필수 | E14: 폰트 이름·텍스트 정규화(CJK 로컬 이름 매칭) | F14: - | G14: crates.io
A15: serde / serde_json | B15: 1 | C15: office2pdf | D15: 런타임 필수 | E15: 설정·메타데이터 직렬화 | F15: - | G15: crates.io
A16: thiserror | B16: 2 | C16: office2pdf | D16: 런타임 필수 | E16: 라이브러리 오류 타입 정의 | F16: - | G16: crates.io
A17: tracing | B17: 0.1 | C17: office2pdf | D17: 런타임 필수 | E17: 구조적 로깅(미지원 요소 경고 채널) | F17: - | G17: crates.io
A18: lopdf | B18: 0.39 | C18: office2pdf | D18: 옵션(pdf-ops) | E18: PDF 병합·분할 및 스트리밍 청크 병합 | F18: - | G18: crates.io | H18: CLI는 항상 활성화
A19: wasm-bindgen | B19: 0.2 | C19: office2pdf | D19: 옵션(wasm) | E19: JavaScript 바인딩 생성 | F19: - | G19: crates.io
A20: ts-rs | B20: 12 | C20: office2pdf | D20: 옵션(typescript) | E20: TypeScript 타입 정의 생성 | F20: - | G20: crates.io
A21: getrandom | B21: 0.2 / 0.3 | C21: office2pdf | D21: 타깃별(wasm32) | E21: wasm32에서 js / wasm_js 백엔드 고정 | F21: - | G21: crates.io | H21: 두 메이저 버전 동시 고정
A22: web-time | B22: 1.1 | C22: office2pdf | D22: 타깃별(wasm32) | E22: std::time 패닉 회피용 브라우저 시계 shim | F22: - | G22: crates.io | H22: wasm 피처와 분리 유지
A23: clap | B23: 4 | C23: office2pdf-cli | D23: 런타임 필수 | E23: CLI 인자 파싱(derive) | F23: - | G23: crates.io
A24: anyhow | B24: 1 | C24: office2pdf-cli | D24: 런타임 필수 | E24: CLI 오류 처리 | F24: - | G24: crates.io
A25: rayon | B25: 1 | C25: office2pdf-cli | D25: 런타임 필수 | E25: 일괄 변환 병렬화(--jobs) | F25: - | G25: crates.io | H25: wasm32 빌드에서는 제외 필요
A26: tiny_http | B26: 0.12 | C26: office2pdf-cli | D26: 옵션(server) | E26: HTTP 변환 서버 | F26: - | G26: crates.io
A27: criterion | B27: 0.5 | C27: office2pdf | D27: 개발(dev) | E27: 변환 성능 벤치마크 하네스 | F27: - | G27: crates.io | H27: wasm32 타깃에서 제외(rayon 의존)
A28: pdf-extract | B28: 0.10 | C28: office2pdf | D28: 개발(dev) | E28: PDF 텍스트 추출 기반 왕복 검증 | F28: - | G28: crates.io
A29: paste | B29: 1 | C29: office2pdf | D29: 개발(dev) | E29: 테스트 매크로 식별자 결합 | F29: - | G29: crates.io
A30: wasm-bindgen-test | B30: 0.3 | C30: office2pdf | D30: 개발(dev, wasm32) | E30: WASM 통합 테스트 하네스 | F30: - | G30: crates.io
D32: 의존 크레이트 항목 수 | E32: =COUNTA($A$5:$A$30) -> 26
D33: 런타임 필수 | E33: =COUNTIF($D$5:$D$30,"런타임 필수") -> 16
D34: 옵션 피처 게이트 | E34: =COUNTIF($D$5:$D$30,"옵션*") -> 4
D35: 개발 전용 | E35: =COUNTIF($D$5:$D$30,"개발*") -> 4
D36: 포크/패치 적용 | E36: =COUNTIF($F$5:$F$30,"포크 적용") -> 2
A38: 'Zero external dependencies'는 런타임 외부 프로세스(LibreOffice, Chromium, Docker) 비의존을 의미하며, Rust 크레이트 의존성은 위와 같이 존재합니다. 파싱 크레이트 2종은 패닉 안전성 및 파싱 관용도 개선을 위해 메인테이너 본인의 포크 브랜치로 [patch.crates-io] 고정되어 있습니다(crates.io 배포 이식성 문제는 v0.6.3에서 해소).

Sheet 09_리스크_로드맵
A1: 09. 비기능 요구사항 · 구현 단계 · 리스크 · 문서-구현 격차
A2: 출처: PRD.md 4·8·10장, METHODOLOGY.md, v0.6.4 릴리스 노트, 소스 대조 결과.
A4: 1. 비기능 요구사항 (PRD 4장)
B5: 범주 | C5: 요구사항 | D5: 현황 근거 | E5: 충족 판단
B6: 성능 | C6: 자릿수 단위 회귀 방지. 통제된 반복 가능 벤치마크에서만 제품 SLA 수립 | D6: CI는 변환당 30초 안전 상한만 적용, criterion 벤치마크 별도 운영 | E6: 정책 수립 완료
B7: 메모리 | C7: 100페이지 문서 기준 500MB 미만 | D7: XLSX 스트리밍 모드(행 청크)로 사용량 상한 제어 수단 제공 | E7: 측정치 미공개
B8: 바이너리 크기 | C8: CLI 50MB 미만(폰트 포함) | D8: typst-kit embed-fonts 로 폰트 내장, 6개 타깃 프리빌트 아카이브 배포 | E8: 측정치 미공개
B9: 플랫폼 | C9: Windows, macOS, Linux | D9: CI 3중 OS 매트릭스 + 6개 타깃 릴리스 아티팩트(musl 정적 포함) | E9: 충족
B10: 오류 처리 | C10: 파싱 불가 요소는 경고와 함께 건너뛰고 전체 변환 계속 | D10: Error 열거형의 UnsupportedElement/PartialElement/FallbackUsed/ParseSkipped 진단 변형 | E10: 충족
B11: 폰트 폴백 | C11: 시스템 폰트 탐색 + 내장 기본 폰트 | D11: render/font_subst.rs, font_context.rs, macOS Office 폰트 자동 탐색, 임베드 폰트 추출 | E11: 충족
B12: 출력 준수 표준 | C12: PDF 1.7 기본, PDF/A 옵션 | D12: PDF/A-2b, 태그 PDF, PDF/UA-1 까지 확장 구현 | E12: 요구 초과 달성
A14: 2. 성능 측정 정책 (PRD 4.1장)
B15: • | C15: 공용 러너 CI의 변환당 30초 상한은 총체적 회귀 탐지용이며 제품 SLA·P95 주장이 아님
B16: • | C16: 제품 목표치는 버전 고정된 실사용 픽스처, 하드웨어, OS, 폰트 세트, 캐시 상태를 명시해야 함
B17: • | C17: 릴리스 차단 지연 목표 도입 전 전용 러너에서 시나리오당 100회 이상 표본으로 중위수·P95·P99 보고
B18: • | C18: 벤치마크 기준선은 버전 관리하며, 목표 변경 시 전후 측정치와 근거를 PR에 기술
A20: 3. 구현 단계 (PRD 8장) 및 진행 판단
B21: 단계 | C21: 범위 | D21: 현 상태 근거 | E21: 판단
B22: Phase 1 — MVP | C22: 워크스페이스·CI 구성, IR 정의, 3포맷 P0 기능 → Typst → PDF, 기본 CLI | D22: v0.1.0~v0.2.0 시점에 완료 | E22: 완료
B23: Phase 2 — 서식/스타일 | C23: P1 전량, 폰트 임베딩·폴백, 오류 처리 강화 | D23: v0.4.0 임베드 폰트 추출·폰트 자동 탐색으로 달성 | E23: 완료
B24: Phase 3 — 고급 기능 | C24: P2 전량, PDF/A, 성능 최적화, 일괄 변환 | D24: PDF/A-2b·태그 PDF·PDF/UA, --jobs 병렬화, 스트리밍 모드 | E24: 완료
B25: Phase 4 — 마감 | C25: P3 가능 범위, 엣지 케이스, 문서·예제·crates.io 배포 | D25: crates.io 배포 및 v0.6.x 충실도 버그 수정 집중 구간 | E25: 진행 중
A27: 4. 리스크 및 완화 (PRD 10장)
B28: 리스크 | C28: 영향 | D28: 완화 전략 | E28: 실제 적용 근거
B29: OOXML 명세 복잡도 | C29: 파싱 크레이트가 전체 요소를 지원하지 못함 | D29: 미지원 요소 건너뛰기 + 경고 로그 | E29: ParseSkipped/UnsupportedElement 진단 변형
B30: Typst 표현력 한계 | C30: 일부 레이아웃을 Typst로 표현 불가 | D30: Typst 표현 범위 내 최선 근사 | E30: v0.6.4 그림자 블러를 반투명 링 적층으로 근사(#400)
B31: 폰트 호환성 | C31: 원본 폰트 부재 | D31: 시스템 폰트 탐색 + 폴백 매핑 | E31: macOS Office 폰트 자동 탐색, CJK 로컬 이름 매칭
B32: 파싱 크레이트 유지보수 중단 | C32: 의존 크레이트 방치 위험 | D32: 포크 준비, 핵심 파서 자체 구현 검토 | E32: docx-rs·umya-spreadsheet 포크 고정, PPTX는 quick-xml 기반 자체 파서
A34: 5. 문서-구현 격차 (본 워크북 대조 결과)
B35: README 미기재 CLI 옵션 | C35: --tagged, --pdf-ua, --streaming, --streaming-chunk-size, --metrics, --jobs (6건) | D35: 03_CLI_옵션 시트 | E35: 문서 갱신 후보
B36: README 미기재 서브커맨드 | C36: merge, split, server (3건) | D36: main.rs Commands 열거형 | E36: 문서 갱신 후보
B37: README 축소 기술 | C37: XLSX 조건부 서식은 DataBar/IconSet만 기재되나 ColorScale·cellIs·텍스트 규칙도 구현 | D37: parser/cond_fmt.rs | E37: 문서 갱신 후보
B38: README 기재 대비 근거 미확인 | C38: PPTX 발표자 노트(speaker notes) — main 소스에서 notesSlide 처리 미검출 | D38: 02_기능_매트릭스 F-036 | E38: 재확인 필요
B39: PRD 기술 스택 불일치 | C39: PRD는 PPTX 파서로 ppt-rs 를 명시하나 실제로는 quick-xml 기반 자체 구현 | D39: Cargo.toml 대조 | E39: PRD 갱신 후보
A41: 본 시트의 '격차'는 결함 지적이 아니라, 문서와 구현이 서로 다른 속도로 진화한 지점을 표시한 것입니다. 각 항목은 해당 시트의 근거 셀에서 원천 파일 경로를 확인할 수 있습니다.
